Workbook
Name Slicer_Branch: #N/A
Name Slicer_Product: #N/A
Name Slicer_Sales_Manager: #N/A

Sheet Revenue
A1: SN | B1: ProdCode | C1: Product | D1: Branch | E1: Sales Manager | F1: MonthCode | G1: Month | H1: Sales Budget | I1: Actual Sales | J1: Expense Budget | K1: Actual Expense | L1: △Sales Variance | M1: △Expense Variance | N1: Actual Net Profit | O1: Budget Net Profit | P1: Net Profit Variance | Q1: Sales_Variance % | R1: Expense_Variance % | S1: Net_Profit_Variance % | T1: Net _Profit_Margin | U1: Product_Branch
A2: 1 | B2: 100 | C2: =VLOOKUP(B2,Products!A:C,2,FALSE) -> Mango | D2: Lagos | E2: =_xlfn.XLOOKUP(D2,'Sales Manager'!$A$2:$A$6,'Sales Manager'!$B$2:$B$6,"") -> Adaora Okafor | F2: 1 | G2: Jan | H2: 1000 | I2: 2159 | J2: {=_xlfn.XLOOKUP(C2&D2&F2,Expense!$C$2:$C$601&Expense!$D$2:$D$601&Expense!$E$2:$E$601,Expense!$G$2:$G$601,"")} -> 500 | K2: {=_xlfn.XLOOKUP(C2&D2&F2,Expense!$C$2:$C$601&Expense!$D$2:$D$601&Expense!$E$2:$E$601,Expense!$H$2:$H$601,"")} -> 500 | L2: =I2-H2 -> 1159 | M2: =Master_Table[[#This Row],[Expense Budget]]-Master_Table[[#This Row],[Actual Expense]] -> 0 | N2: =I2-K2 -> 1659 | O2: =H2-J2 -> 500 | P2: =N2-O2 -> 1159 | Q2: =Master_Table[[#This Row],[△Sales Variance]]/Master_Table[[#This Row],[Sales Budget]] -> 1.159 | R2: =Master_Table[[#This Row],[△Expense Variance]]/Master_Table[[#This Row],[Expense Budget]] -> 0 | S2: =Master_Table[[#This Row],[Net Profit Variance]]/Master_Table[[#This Row],[Budget Net Profit]] -> 2.318 | T2: =Master_Table[[#This Row],[Actual Net Profit]]/Master_Table[[#This Row],[Actual Sales]] -> 0.7684113 | U2: =_xlfn.TEXTJOIN(" - ", TRUE, Master_Table[[#This Row],[Product]], Master_Table[[#This Row],[Branch]]) -> Mango - Lagos
A3: 2 | B3: 100 | C3: =VLOOKUP(B3,Products!A:C,2,FALSE) -> Mango | D3: Lagos | E3: =_xlfn.XLOOKUP(D3,'Sales Manager'!$A$2:$A$6,'Sales Manager'!$B$2:$B$6,"") -> Adaora Okafor | F3: 2 | G3: Feb | H3: 3000 | I3: 5422 | J3: {=_xlfn.XLOOKUP(C3&D3&F3,Expense!$C$2:$C$601&Expense!$D$2:$D$601&Expense!$E$2:$E$601,Expense!$G$2:$G$601,"")} -> 600 | K3: {=_xlfn.XLOOKUP(C3&D3&F3,Expense!$C$2:$C$601&Expense!$D$2:$D$601&Expense!$E$2:$E$601,Expense!$H$2:$H$601,"")} -> 500 | L3: =I3-H3 -> 2422 | M3: =Master_Table[[#This Row],[Expense Budget]]-Master_Table[[#This Row],[Actual Expense]] -> 100 | N3: =I3-K3 -> 4922 | O3: =H3-J3 -> 2400 | P3: =N3-O3 -> 2522 | Q3: =Master_Table[[#This Row],[△Sales Variance]]/Master_Table[[#This Row],[Sales Budget]] -> 0.80733333 | R3: =Master_Table[[#This Row],[△Expense Variance]]/Master_Table[[#This Row],[Expense Budget]] -> 0.16666667 | S3: =Master_Table[[#This Row],[Net Profit Variance]]/Master_Table[[#This Row],[Budget Net Profit]] -> 1.0508333 | T3: =Master_Table[[#This Row],[Actual Net Profit]]/Master_Table[[#This Row],[Actual Sales]] -> 0.90778311 | U3: =_xlfn.TEXTJOIN(" - ", TRUE, Master_Table[[#This Row],[Product]], Master_Table[[#This Row],[Branch]]) -> Mango - Lagos
A4: 3 | B4: 100 | C4: =VLOOKUP(B4,Products!A:C,2,FALSE) -> Mango | D4: Lagos | E4: =_xlfn.XLOOKUP(D4,'Sales Manager'!$A$2:$A$6,'Sales Manager'!$B$2:$B$6,"") -> Adaora Okafor | F4: 3 | G4: Mar | H4: 5000 | I4: 7998 | J4: {=_xlfn.XLOOKUP(C4&D4&F4,Expense!$C$2:$C$601&Expense!$D$2:$D$601&Expense!$E$2:$E$601,Expense!$G$2:$G$601,"")} -> 2500 | K4: {=_xlfn.XLOOKUP(C4&D4&F4,Expense!$C$2:$C$601&Expense!$D$2:$D$601&Expense!$E$2:$E$601,Expense!$H$2:$H$601,"")} -> 2200 | L4: =I4-H4 -> 2998 | M4: =Master_Table[[#This Row],[Expense Budget]]-Master_Table[[#This Row],[Actual Expense]] -> 300 | N4: =I4-K4 -> 5798 | O4: =H4-J4 -> 2500 | P4: =N4-O4 -> 3298 | Q4: =Master_Table[[#This Row],[△Sales Variance]]/Master_Table[[#This Row],[Sales Budget]] -> 0.5996 | R4: =Master_Table[[#This Row],[△Expense Variance]]/Master_Table[[#This Row],[Expense Budget]] -> 0.12 | S4: =Master_Table[[#This Row],[Net Profit Variance]]/Master_Table[[#This Row],[Budget Net Profit]] -> 1.3192 | T4: =Master_Table[[#This Row],[Actual Net Profit]]/Master_Table[[#This Row],[Actual Sales]] -> 0.72493123 | U4: =_xlfn.TEXTJOIN(" - ", TRUE, Master_Table[[#This Row],[Product]], Master_Table[[#This Row],[Branch]]) -> Mango - Lagos
A5: 4 | B5: 100 | C5: =VLOOKUP(B5,Products!A:C,2,FALSE) -> Mango | D5: Lagos | E5: =_xlfn.XLOOKUP(D5,'Sales Manager'!$A$2:$A$6,'Sales Manager'!$B$2:$B$6,"") -> Adaora Okafor | F5: 4 | G5: Apr | H5: 7000 | I5: 2265 | J5: {=_xlfn.XLOOKUP(C5&D5&F5,Expense!$C$2:$C$601&Expense!$D$2:$D$601&Expense!$E$2:$E$601,Expense!$G$2:$G$601,"")} -> 1750 | K5: {=_xlfn.XLOOKUP(C5&D5&F5,Expense!$C$2:$C$601&Expense!$D$2:$D$601&Expense!$E$2:$E$601,Expense!$H$2:$H$601,"")} -> 1350 | L5: =I5-H5 -> -4735 | M5: =Master_Table[[#This Row],[Expense Budget]]-Master_Table[[#This Row],[Actual Expense]] -> 400 | N5: =I5-K5 -> 915 | O5: =H5-J5 -> 5250 | P5: =N5-O5 -> -4335 | Q5: =Master_Table[[#This Row],[△Sales Variance]]/Master_Table[[#This Row],[Sales Budget]] -> -0.67642857 | R5: =Master_Table[[#This Row],[△Expense Variance]]/Master_Table[[#This Row],[Expense Budget]] -> 0.22857143 | S5: =Master_Table[[#This Row],[Net Profit Variance]]/Master_Table[[#This Row],[Budget Net Profit]] -> -0.82571429 | T5: =Master_Table[[#This Row],[Actual Net Profit]]/Master_Table[[#This Row],[Actual Sales]] -> 0.40397351 | U5: =_xlfn.TEXTJOIN(" - ", TRUE, Master_Table[[#This Row],[Product]], Master_Table[[#This Row],[Branch]]) -> Mango - Lagos
A6: 5 | B6: 100 | C6: =VLOOKUP(B6,Products!A:C,2,FALSE) -> Mango | D6: Lagos | E6: =_xlfn.XLOOKUP(D6,'Sales Manager'!$A$2:$A$6,'Sales Manager'!$B$2:$B$6,"") -> Adaora Okafor | F6: 5 | G6: May | H6: 5000 | I6: 4766 | J6: {=_xlfn.XLOOKUP(C6&D6&F6,Expense!$C$2:$C$601&Expense!$D$2:$D$601&Expense!$E$2:$E$601,Expense!$G$2:$G$601,"")} -> 1000 | K6: {=_xlfn.XLOOKUP(C6&D6&F6,Expense!$C$2:$C$601&Expense!$D$2:$D$601&Expense!$E$2:$E$601,Expense!$H$2:$H$601,"")} -> 600 | L6: =I6-H6 -> -234 | M6: =Master_Table[[#This Row],[Expense Budget]]-Master_Table[[#This Row],[Actual Expense]] -> 400 | N6: =I6-K6 -> 4166 | O6: =H6-J6 -> 4000 | P6: =N6-O6 -> 166 | Q6: =Master_Table[[#This Row],[△Sales Variance]]/Master_Table[[#This Row],[Sales Budget]] -> -0.0468 | R6: =Master_Table[[#This Row],[△Expense Variance]]/Master_Table[[#This Row],[Expense Budget]] -> 0.4 | S6: =Master_Table[[#This Row],[Net Profit Variance]]/Master_Table[[#This Row],[Budget Net Profit]] -> 0.0415 | T6: =Master_Table[[#This Row],[Actual Net Profit]]/Master_Table[[#This Row],[Actual Sales]] -> 0.87410827 | U6: =_xlfn.TEXTJOIN(" - ", TRUE, Master_Table[[#This Row],[Product]], Master_Table[[#This Row],[Branch]]) -> Mango - Lagos
A7: 6 | B7: 100 | C7: =VLOOKUP(B7,Products!A:C,2,FALSE) -> Mango | D7: Lagos | E7: =_xlfn.XLOOKUP(D7,'Sales Manager'!$A$2:$A$6,'Sales Manager'!$B$2:$B$6,"") -> Adaora Okafor | F7: 6 | G7: Jun | H7: 7000 | I7: 8121 | J7: {=_xlfn.XLOOKUP(C7&D7&F7,Expense!$C$2:$C$601&Expense!$D$2:$D$601&Expense!$E$2:$E$601,Expense!$G$2:$G$601,"")} -> 1400 | K7: {=_xlfn.XLOOKUP(C7&D7&F7,Expense!$C$2:$C$601&Expense!$D$2:$D$601&Expense!$E$2:$E$601,Expense!$H$2:$H$601,"")} -> 1300 | L7: =I7-H7 -> 1121 | M7: =Master_Table[[#This Row],[Expense Budget]]-Master_Table[[#This Row],[Actual Expense]] -> 100 | N7: =I7-K7 -> 6821 | O7: =H7-J7 -> 5600 | P7: =N7-O7 -> 1221 | Q7: =Master_Table[[#This Row],[△Sales Variance]]/Master_Table[[#This Row],[Sales Budget]] -> 0.16014286 | R7: =Master_Table[[#This Row],[△Expense Variance]]/Master_Table[[#This Row],[Expense Budget]] -> 0.071428571 | S7: =Master_Table[[#This Row],[Net Profit Variance]]/Master_Table[[#This Row],[Budget Net Profit]] -> 0.21803571 | T7: =Master_Table[[#This Row],[Actual Net Profit]]/Master_Table[[#This Row],[Actual Sales]] -> 0.83992119 | U7: =_xlfn.TEXTJOIN(" - ", TRUE, Master_Table[[#This Row],[Product]], Master_Table[[#This Row],[Branch]]) -> Mango - Lagos
A8: 7 | B8: 100 | C8: =VLOOKUP(B8,Products!A:C,2,FALSE) -> Mango | D8: Lagos | E8: =_xlfn.XLOOKUP(D8,'Sales Manager'!$A$2:$A$6,'Sales Manager'!$B$2:$B$6,"") -> Adaora Okafor | F8: 7 | G8: Jul | H8: 5000 | I8: 8342 | J8: {=_xlfn.XLOOKUP(C8&D8&F8,Expense!$C$2:$C$601&Expense!$D$2:$D$601&Expense!$E$2:$E$601,Expense!$G$2:$G$601,"")} -> 2500 | K8: {=_xlfn.XLOOKUP(C8&D8&F8,Expense!$C$2:$C$601&Expense!$D$2:$D$601&Expense!$E$2:$E$601,Expense!$H$2:$H$601,"")} -> 2400 | L8: =I8-H8 -> 3342 | M8: =Master_Table[[#This Row],[Expense Budget]]-Master_Table[[#This Row],[Actual Expense]] -> 100 | N8: =I8-K8 -> 5942 | O8: =H8-J8 -> 2500 | P8: =N8-O8 -> 3442 | Q8: =Master_Table[[#This Row],[△Sales Variance]]/Master_Table[[#This Row],[Sales Budget]] -> 0.6684 | R8: =Master_Table[[#This Row],[△Expense Variance]]/Master_Table[[#This Row],[Expense Budget]] -> 0.04 | S8: =Master_Table[[#This Row],[Net Profit Variance]]/Master_Table[[#This Row],[Budget Net Profit]] -> 1.3768 | T8: =Master_Table[[#This Row],[Actual Net Profit]]/Master_Table[[#This Row],[Actual Sales]] -> 0.71229921 | U8: =_xlfn.TEXTJOIN(" - ", TRUE, Master_Table[[#This Row],[Product]], Master_Table[[#This Row],[Branch]]) -> Mango - Lagos
A9: 8 | B9: 100 | C9: =VLOOKUP(B9,Products!A:C,2,FALSE) -> Mango | D9: Lagos | E9: =_xlfn.XLOOKUP(D9,'Sales Manager'!$A$2:$A$6,'Sales Manager'!$B$2:$B$6,"") -> Adaora Okafor | F9: 8 | G9: Aug | H9: 1000 | I9: 6412 | J9: {=_xlfn.XLOOKUP(C9&D9&F9,Expense!$C$2:$C$601&Expense!$D$2:$D$601&Expense!$E$2:$E$601,Expense!$G$2:$G$601,"")} -> 333.33333 | K9: {=_xlfn.XLOOKUP(C9&D9&F9,Expense!$C$2:$C$601&Expense!$D$2:$D$601&Expense!$E$2:$E$601,Expense!$H$2:$H$601,"")} -> 266.66667 | L9: =I9-H9 -> 5412 | M9: =Master_Table[[#This Row],[Expense Budget]]-Master_Table[[#This Row],[Actual Expense]] -> 66.666667 | N9: =I9-K9 -> 6145.3333 | O9: =H9-J9 -> 666.66667 | P9: =N9-O9 -> 5478.6667 | Q9: =Master_Table[[#This Row],[△Sales Variance]]/Master_Table[[#This Row],[Sales Budget]] -> 5.412 | R9: =Master_Table[[#This Row],[△Expense Variance]]/Master_Table[[#This Row],[Expense Budget]] -> 0.2 | S9: =Master_Table[[#This Row],[Net Profit Variance]]/Master_Table[[#This Row],[Budget Net Profit]] -> 8.218 | T9: =Master_Table[[#This Row],[Actual Net Profit]]/Master_Table[[#This Row],[Actual Sales]] -> 0.95841131 | U9: =_xlfn.TEXTJOIN(" - ", TRUE, Master_Table[[#This Row],[Product]], Master_Table[[#This Row],[Branch]]) -> Mango - Lagos
A10: 9 | B10: 100 | C10: =VLOOKUP(B10,Products!A:C,2,FALSE) -> Mango | D10: Lagos | E10: =_xlfn.XLOOKUP(D10,'Sales Manager'!$A$2:$A$6,'Sales Manager'!$B$2:$B$6,"") -> Adaora Okafor | F10: 9 | G10: Sept | H10: 8000 | I10: 3324 | J10: {=_xlfn.XLOOKUP(C10&D10&F10,Expense!$C$2:$C$601&Expense!$D$2:$D$601&Expense!$E$2:$E$601,Expense!$G$2:$G$601,"")} -> 1600 | K10: {=_xlfn.XLOOKUP(C10&D10&F10,Expense!$C$2:$C$601&Expense!$D$2:$D$601&Expense!$E$2:$E$601,Expense!$H$2:$H$601,"")} -> 1400 | L10: =I10-H10 -> -4676 | M10: =Master_Table[[#This Row],[Expense Budget]]-Master_Table[[#This Row],[Actual Expense]] -> 200 | N10: =I10-K10 -> 1924 | O10: =H10-J10 -> 6400 | P10: =N10-O10 -> -4476 | Q10: =Master_Table[[#This Row],[△Sales Variance]]/Master_Table[[#This Row],[Sales Budget]] -> -0.5845 | R10: =Master_Table[[#This Row],[△Expense Variance]]/Master_Table[[#This Row],[Expense Budget]] -> 0.125 | S10: =Master_Table[[#This Row],[Net Profit Variance]]/Master_Table[[#This Row],[Budget Net Profit]] -> -0.699375 | T10: =Master_Table[[#This Row],[Actual Net Profit]]/Master_Table[[#This Row],[Actual Sales]] -> 0.5788207 | U10: =_xlfn.TEXTJOIN(" - ", TRUE, Master_Table[[#This Row],[Product]], Master_Table[[#This Row],[Branch]]) -> Mango - Lagos
A11: 10 | B11: 100 | C11: =VLOOKUP(B11,Products!A:C,2,FALSE) -> Mango | D11: Lagos | E11: =_xlfn.XLOOKUP(D11,'Sales Manager'!$A$2:$A$6,'Sales Manager'!$B$2:$B$6,"") -> Adaora Okafor | F11: 10 | G11: Oct | H11: 7000 | I11: 3142 | J11: {=_xlfn.XLOOKUP(C11&D11&F11,Expense!$C$2:$C$601&Expense!$D$2:$D$601&Expense!$E$2:$E$601,Expense!$G$2:$G$601,"")} -> 1400 | K11: {=_xlfn.XLOOKUP(C11&D11&F11,Expense!$C$2:$C$601&Expense!$D$2:$D$601&Expense!$E$2:$E$601,Expense!$H$2:$H$601,"")} -> 1000 | L11: =I11-H11 -> -3858 | M11: =Master_Table[[#This Row],[Expense Budget]]-Master_Table[[#This Row],[Actual Expense]] -> 400 | N11: =I11-K11 -> 2142 | O11: =H11-J11 -> 5600 | P11: =N11-O11 -> -3458 | Q11: =Master_Table[[#This Row],[△Sales Variance]]/Master_Table[[#This Row],[Sales Budget]] -> -0.55114286 | R11: =Master_Table[[#This Row],[△Expense Variance]]/Master_Table[[#This Row],[Expense Budget]] -> 0.28571429 | S11: =Master_Table[[#This Row],[Net Profit Variance]]/Master_Table[[#This Row],[Budget Net Profit]] -> -0.6175 | T11: =Master_Table[[#This Row],[Actual Net Profit]]/Master_Table[[#This Row],[Actual Sales]] -> 0.68173138 | U11: =_xlfn.TEXTJOIN(" - ", TRUE, Master_Table[[#This Row],[Product]], Master_Table[[#This Row],[Branch]]) -> Mango - Lagos
A12: 11 | B12: 100 | C12: =VLOOKUP(B12,Products!A:C,2,FALSE) -> Mango | D12: Lagos | E12: =_xlfn.XLOOKUP(D12,'Sales Manager'!$A$2:$A$6,'Sales Manager'!$B$2:$B$6,"") -> Adaora Okafor | F12: 11 | G12: Nov | H12: 2000 | I12: 3349 | J12: {=_xlfn.XLOOKUP(C12&D12&F12,Expense!$C$2:$C$601&Expense!$D$2:$D$601&Expense!$E$2:$E$601,Expense!$G$2:$G$601,"")} -> 666.66667 | K12: {=_xlfn.XLOOKUP(C12&D12&F12,Expense!$C$2:$C$601&Expense!$D$2:$D$601&Expense!$E$2:$E$601,Expense!$H$2:$H$601,"")} -> 333.33333 | L12: =I12-H12 -> 1349 | M12: =Master_Table[[#This Row],[Expense Budget]]-Master_Table[[#This Row],[Actual Expense]] -> 333.33333 | N12: =I12-K12 -> 3015.6667 | O12: =H12-J12 -> 1333.3333 | P12: =N12-O12 -> 1682.3333 | Q12: =Master_Table[[#This Row],[△Sales Variance]]/Master_Table[[#This Row],[Sales Budget]] -> 0.6745 | R12: =Master_Table[[#This Row],[△Expense Variance]]/Master_Table[[#This Row],[Expense Budget]] -> 0.5 | S12: =Master_Table[[#This Row],[Net Profit Variance]]/Master_Table[[#This Row],[Budget Net Profit]] -> 1.26175 | T12: =Master_Table[[#This Row],[Actual Net Profit]]/Master_Table[[#This Row],[Actual Sales]] -> 0.9004678 | U12: =_xlfn.TEXTJOIN(" - ", TRUE, Master_Table[[#This Row],[Product]], Master_Table[[#This Row],[Branch]]) -> Mango - Lagos
A13: 12 | B13: 100 | C13: =VLOOKUP(B13,Products!A:C,2,FALSE) -> Mango | D13: Lagos | E13: =_xlfn.XLOOKUP(D13,'Sales Manager'!$A$2:$A$6,'Sales Manager'!$B$2:$B$6,"") -> Adaora Okafor | F13: 12 | G13: Dec | H13: 2000 | I13: 9853 | J13: {=_xlfn.XLOOKUP(C13&D13&F13,Expense!$C$2:$C$601&Expense!$D$2:$D$601&Expense!$E$2:$E$601,Expense!$G$2:$G$601,"")} -> 400 | K13: {=_xlfn.XLOOKUP(C13&D13&F13,Expense!$C$2:$C$601&Expense!$D$2:$D$601&Expense!$E$2:$E$601,Expense!$H$2:$H$601,"")} -> 400 | L13: =I13-H13 -> 7853 | M13: =Master_Table[[#This Row],[Expense Budget]]-Master_Table[[#This Row],[Actual Expense]] -> 0 | N13: =I13-K13 -> 9453 | O13: =H13-J13 -> 1600 | P13: =N13-O13 -> 7853 | Q13: =Master_Table[[#This Row],[△Sales Variance]]/Master_Table[[#This Row],[Sales Budget]] -> 3.9265 | R13: =Master_Table[[#This Row],[△Expense Variance]]/Master_Table[[#This Row],[Expense Budget]] -> 0 | S13: =Master_Table[[#This Row],[Net Profit Variance]]/Master_Table[[#This Row],[Budget Net Profit]] -> 4.908125 | T13: =Master_Table[[#This Row],[Actual Net Profit]]/Master_Table[[#This Row],[Actual Sales]] -> 0.95940323 | U13: =_xlfn.TEXTJOIN(" - ", TRUE, Master_Table[[#This Row],[Product]], Master_Table[[#This Row],[Branch]]) -> Mango - Lagos
A14: 13 | B14: 100 | C14: =VLOOKUP(B14,Products!A:C,2,FALSE) -> Mango | D14: Abuja | E14: =_xlfn.XLOOKUP(D14,'Sales Manager'!$A$2:$A$6,'Sales Manager'!$B$2:$B$6,"") -> Emeka Nwosu | F14: =F2 -> 1 | G14: =G2 -> Jan | H14: 5000 | I14: 3515 | J14: {=_xlfn.XLOOKUP(C14&D14&F14,Expense!$C$2:$C$601&Expense!$D$2:$D$601&Expense!$E$2:$E$601,Expense!$G$2:$G$601,"")} -> 2500 | K14: {=_xlfn.XLOOKUP(C14&D14&F14,Expense!$C$2:$C$601&Expense!$D$2:$D$601&Expense!$E$2:$E$601,Expense!$H$2:$H$601,"")} -> 2400 | L14: =I14-H14 -> -1485 | M14: =Master_Table[[#This Row],[Expense Budget]]-Master_Table[[#This Row],[Actual Expense]] -> 100 | N14: =I14-K14 -> 1115 | O14: =H14-J14 -> 2500 | P14: =N14-O14 -> -1385 | Q14: =Master_Table[[#This Row],[△Sales Variance]]/Master_Table[[#This Row],[Sales Budget]] -> -0.297 | R14: =Master_Table[[#This Row],[△Expense Variance]]/Master_Table[[#This Row],[Expense Budget]] -> 0.04 | S14: =Master_Table[[#This Row],[Net Profit Variance]]/Master_Table[[#This Row],[Budget Net Profit]] -> -0.554 | T14: =Master_Table[[#This Row],[Actual Net Profit]]/Master_Table[[#This Row],[Actual Sales]] -> 0.31721195 | U14: =_xlfn.TEXTJOIN(" - ", TRUE, Master_Table[[#This Row],[Product]], Master_Table[[#This Row],[Branch]]) -> Mango - Abuja
A15: 14 | B15: 100 | C15: =VLOOKUP(B15,Products!A:C,2,FALSE) -> Mango | D15: Abuja | E15: =_xlfn.XLOOKUP(D15,'Sales Manager'!$A$2:$A$6,'Sales Manager'!$B$2:$B$6,"") -> Emeka Nwosu | F15: =F3 -> 2 | G15: =G3 -> Feb | H15: 2000 | I15: 6147 | J15: {=_xlfn.XLOOKUP(C15&D15&F15,Expense!$C$2:$C$601&Expense!$D$2:$D$601&Expense!$E$2:$E$601,Expense!$G$2:$G$601,"")} -> 400 | K15: {=_xlfn.XLOOKUP(C15&D15&F15,Expense!$C$2:$C$601&Expense!$D$2:$D$601&Expense!$E$2:$E$601,Expense!$H$2:$H$601,"")} -> 500 | L15: =I15-H15 -> 4147 | M15: =Master_Table[[#This Row],[Expense Budget]]-Master_Table[[#This Row],[Actual Expense]] -> -100 | N15: =I15-K15 -> 5647 | O15: =H15-J15 -> 1600 | P15: =N15-O15 -> 4047 | Q15: =Master_Table[[#This Row],[△Sales Variance]]/Master_Table[[#This Row],[Sales Budget]] -> 2.0735 | R15: =Master_Table[[#This Row],[△Expense Variance]]/Master_Table[[#This Row],[Expense Budget]] -> -0.25 | S15: =Master_Table[[#This Row],[Net Profit Variance]]/Master_Table[[#This Row],[Budget Net Profit]] -> 2.529375 | T15: =Master_Table[[#This Row],[Actual Net Profit]]/Master_Table[[#This Row],[Actual Sales]] -> 0.91865951 | U15: =_xlfn.TEXTJOIN(" - ", TRUE, Master_Table[[#This Row],[Product]], Master_Table[[#This Row],[Branch]]) -> Mango - Abuja
A16: 15 | B16: 100 | C16: =VLOOKUP(B16,Products!A:C,2,FALSE) -> Mango | D16: Abuja | E16: =_xlfn.XLOOKUP(D16,'Sales Manager'!$A$2:$A$6,'Sales Manager'!$B$2:$B$6,"") -> Emeka Nwosu | F16: =F4 -> 3 | G16: =G4 -> Mar | H16: 1000 | I16: 7831 | J16: {=_xlfn.XLOOKUP(C16&D16&F16,Expense!$C$2:$C$601&Expense!$D$2:$D$601&Expense!$E$2:$E$601,Expense!$G$2:$G$601,"")} -> 250 | K16: {=_xlfn.XLOOKUP(C16&D16&F16,Expense!$C$2:$C$601&Expense!$D$2:$D$601&Expense!$E$2:$E$601,Expense!$H$2:$H$601,"")} -> 250 | L16: =I16-H16 -> 6831 | M16: =Master_Table[[#This Row],[Expense Budget]]-Master_Table[[#This Row],[Actual Expense]] -> 0 | N16: =I16-K16 -> 7581 | O16: =H16-J16 -> 750 | P16: =N16-O16 -> 6831 | Q16: =Master_Table[[#This Row],[△Sales Variance]]/Master_Table[[#This Row],[Sales Budget]] -> 6.831 | R16: =Master_Table[[#This Row],[△Expense Variance]]/Master_Table[[#This Row],[Expense Budget]] -> 0 | S16: =Master_Table[[#This Row],[Net Profit Variance]]/Master_Table[[#This Row],[Budget Net Profit]] -> 9.108 | T16: =Master_Table[[#This Row],[Actual Net Profit]]/Master_Table[[#This Row],[Actual Sales]] -> 0.9680756 | U16: =_xlfn.TEXTJOIN(" - ", TRUE, Master_Table[[#This Row],[Product]], Master_Table[[#This Row],[Branch]]) -> Mango - Abuja
A17: 16 | B17: 100 | C17: =VLOOKUP(B17,Products!A:C,2,FALSE) -> Mango | D17: Abuja | E17: =_xlfn.XLOOKUP(D17,'Sales Manager'!$A$2:$A$6,'Sales Manager'!$B$2:$B$6,"") -> Emeka Nwosu | F17: =F5 -> 4 | G17: =G5 -> Apr | H17: 3000 | I17: 7346 | J17: {=_xlfn.XLOOKUP(C17&D17&F17,Expense!$C$2:$C$601&Expense!$D$2:$D$601&Expense!$E$2:$E$601,Expense!$G$2:$G$601,"")} -> 600 | K17: {=_xlfn.XLOOKUP(C17&D17&F17,Expense!$C$2:$C$601&Expense!$D$2:$D$601&Expense!$E$2:$E$601,Expense!$H$2:$H$601,"")} -> 600 | L17: =I17-H17 -> 4346 | M17: =Master_Table[[#This Row],[Expense Budget]]-Master_Table[[#This Row],[Actual Expense]] -> 0 | N17: =I17-K17 -> 6746 | O17: =H17-J17 -> 2400 | P17: =N17-O17 -> 4346 | Q17: =Master_Table[[#This Row],[△Sales Variance]]/Master_Table[[#This Row],[Sales Budget]] -> 1.4486667 | R17: =Master_Table[[#This Row],[△Expense Variance]]/Master_Table[[#This Row],[Expense Budget]] -> 0 | S17: =Master_Table[[#This Row],[Net Profit Variance]]/Master_Table[[#This Row],[Budget Net Profit]] -> 1.8108333 | T17: =Master_Table[[#This Row],[Actual Net Profit]]/Master_Table[[#This Row],[Actual Sales]] -> 0.9183229 | U17: =_xlfn.TEXTJOIN(" - ", TRUE, Master_Table[[#This Row],[Product]], Master_Table[[#This Row],[Branch]]) -> Mango - Abuja
A18: 17 | B18: 100 | C18: =VLOOKUP(B18,Products!A:C,2,FALSE) -> Mango | D18: Abuja | E18: =_xlfn.XLOOKUP(D18,'Sales Manager'!$A$2:$A$6,'Sales Manager'!$B$2:$B$6,"") -> Emeka Nwosu | F18: =F6 -> 5 | G18: =G6 -> May | H18: 4000 | I18: 2435 | J18: {=_xlfn.XLOOKUP(C18&D18&F18,Expense!$C$2:$C$601&Expense!$D$2:$D$601&Expense!$E$2:$E$601,Expense!$G$2:$G$601,"")} -> 2000 | K18: {=_xlfn.XLOOKUP(C18&D18&F18,Expense!$C$2:$C$601&Expense!$D$2:$D$601&Expense!$E$2:$E$601,Expense!$H$2:$H$601,"")} -> 1800 | L18: =I18-H18 -> -1565 | M18: =Master_Table[[#This Row],[Expense Budget]]-Master_Table[[#This Row],[Actual Expense]] -> 200 | N18: =I18-K18 -> 635 | O18: =H18-J18 -> 2000 | P18: =N18-O18 -> -1365 | Q18: =Master_Table[[#This Row],[△Sales Variance]]/Master_Table[[#This Row],[Sales Budget]] -> -0.39125 | R18: =Master_Table[[#This Row],[△Expense Variance]]/Master_Table[[#This Row],[Expense Budget]] -> 0.1 | S18: =Master_Table[[#This Row],[Net Profit Variance]]/Master_Table[[#This Row],[Budget Net Profit]] -> -0.6825 | T18: =Master_Table[[#This Row],[Actual Net Profit]]/Master_Table[[#This Row],[Actual Sales]] -> 0.26078029 | U18: =_xlfn.TEXTJOIN(" - ", TRUE, Master_Table[[#This Row],[Product]], Master_Table[[#This Row],[Branch]]) -> Mango - Abuja
A19: 18 | B19: 100 | C19: =VLOOKUP(B19,Products!A:C,2,FALSE) -> Mango | D19: Abuja | E19: =_xlfn.XLOOKUP(D19,'Sales Manager'!$A$2:$A$6,'Sales Manager'!$B$2:$B$6,"") -> Emeka Nwosu | F19: =F7 -> 6 | G19: =G7 -> Jun | H19: 7000 | I19: 3018 | J19: {=_xlfn.XLOOKUP(C19&D19&F19,Expense!$C$2:$C$601&Expense!$D$2:$D$601&Expense!$E$2:$E$601,Expense!$G$2:$G$601,"")} -> 3500 | K19: {=_xlfn.XLOOKUP(C19&D19&F19,Expense!$C$2:$C$601&Expense!$D$2:$D$601&Expense!$E$2:$E$601,Expense!$H$2:$H$601,"")} -> 3100 | L19: =I19-H19 -> -3982 | M19: =Master_Table[[#This Row],[Expense Budget]]-Master_Table[[#This Row],[Actual Expense]] -> 400 | N19: =I19-K19 -> -82 | O19: =H19-J19 -> 3500 | P19: =N19-O19 -> -3582 | Q19: =Master_Table[[#This Row],[△Sales Variance]]/Master_Table[[#This Row],[Sales Budget]] -> -0.56885714 | R19: =Master_Table[[#This Row],[△Expense Variance]]/Master_Table[[#This Row],[Expense Budget]] -> 0.11428571 | S19: =Master_Table[[#This Row],[Net Profit Variance]]/Master_Table[[#This Row],[Budget Net Profit]] -> -1.0234286 | T19: =Master_Table[[#This Row],[Actual Net Profit]]/Master_Table[[#This Row],[Actual Sales]] -> -0.027170311 | U19: =_xlfn.TEXTJOIN(" - ", TRUE, Master_Table[[#This Row],[Product]], Master_Table[[#This Row],[Branch]]) -> Mango - Abuja
A20: 19 | B20: 100 | C20: =VLOOKUP(B20,Products!A:C,2,FALSE) -> Mango | D20: Abuja | E20: =_xlfn.XLOOKUP(D20,'Sales Manager'!$A$2:$A$6,'Sales Manager'!$B$2:$B$6,"") -> Emeka Nwosu | F20: =F8 -> 7 | G20: =G8 -> Jul | H20: 2000 | I20: 5266 | J20: {=_xlfn.XLOOKUP(C20&D20&F20,Expense!$C$2:$C$601&Expense!$D$2:$D$601&Expense!$E$2:$E$601,Expense!$G$2:$G$601,"")} -> 666.66667 | K20: {=_xlfn.XLOOKUP(C20&D20&F20,Expense!$C$2:$C$601&Expense!$D$2:$D$601&Expense!$E$2:$E$601,Expense!$H$2:$H$601,"")} -> 333.33333 | L20: =I20-H20 -> 3266 | M20: =Master_Table[[#This Row],[Expense Budget]]-Master_Table[[#This Row],[Actual Expense]] -> 333.33333 | N20: =I20-K20 -> 4932.6667 | O20: =H20-J20 -> 1333.3333 | P20: =N20-O20 -> 3599.3333 | Q20: =Master_Table[[#This Row],[△Sales Variance]]/Master_Table[[#This Row],[Sales Budget]] -> 1.633 | R20: =Master_Table[[#This Row],[△Expense Variance]]/Master_Table[[#This Row],[Expense Budget]] -> 0.5 | S20: =Master_Table[[#This Row],[Net Profit Variance]]/Master_Table[[#This Row],[Budget Net Profit]] -> 2.6995 | T20: =Master_Table[[#This Row],[Actual Net Profit]]/Master_Table[[#This Row],[Actual Sales]] -> 0.93670085 | U20: =_xlfn.TEXTJOIN(" - ", TRUE, Master_Table[[#This Row],[Product]], Master_Table[[#This Row],[Branch]]) -> Mango - Abuja
A21: 20 | B21: 100 | C21: =VLOOKUP(B21,Products!A:C,2,FALSE) -> Mango | D21: Abuja | E21: =_xlfn.XLOOKUP(D21,'Sales Manager'!$A$2:$A$6,'Sales Manager'!$B$2:$B$6,"") -> Emeka Nwosu | F21: =F9 -> 8 | G21: =G9 -> Aug | H21: 5000 | I21: 9171 | J21: {=_xlfn.XLOOKUP(C21&D21&F21,Expense!$C$2:$C$601&Expense!$D$2:$D$601&Expense!$E$2:$E$601,Expense!$G$2:$G$601,"")} -> 2500 | K21: {=_xlfn.XLOOKUP(C21&D21&F21,Expense!$C$2:$C$601&Expense!$D$2:$D$601&Expense!$E$2:$E$601,Expense!$H$2:$H$601,"")} -> 1900 | L21: =I21-H21 -> 4171 | M21: =Master_Table[[#This Row],[Expense Budget]]-Master_Table[[#This Row],[Actual Expense]] -> 600 | N21: =I21-K21 -> 7271 | O21: =H21-J21 -> 2500 | P21: =N21-O21 -> 4771 | Q21: =Master_Table[[#This Row],[△Sales Variance]]/Master_Table[[#This Row],[Sales Budget]] -> 0.8342 | R21: =Master_Table[[#This Row],[△Expense Variance]]/Master_Table[[#This Row],[Expense Budget]] -> 0.24 | S21: =Master_Table[[#This Row],[Net Profit Variance]]/Master_Table[[#This Row],[Budget Net Profit]] -> 1.9084 | T21: =Master_Table[[#This Row],[Actual Net Profit]]/Master_Table[[#This Row],[Actual Sales]] -> 0.79282521 | U21: =_xlfn.TEXTJOIN(" - ", TRUE, Master_Table[[#This Row],[Product]], Master_Table[[#This Row],[Branch]]) -> Mango - Abuja
A22: 21 | B22: 100 | C22: =VLOOKUP(B22,Products!A:C,2,FALSE) -> Mango | D22: Abuja | E22: =_xlfn.XLOOKUP(D22,'Sales Manager'!$A$2:$A$6,'Sales Manager'!$B$2:$B$6,"") -> Emeka Nwosu | F22: =F10 -> 9 | G22: =G10 -> Sept | H22: 3000 | I22: 6258 | J22: {=_xlfn.XLOOKUP(C22&D22&F22,Expense!$C$2:$C$601&Expense!$D$2:$D$601&Expense!$E$2:$E$601,Expense!$G$2:$G$601,"")} -> 600 | K22: {=_xlfn.XLOOKUP(C22&D22&F22,Expense!$C$2:$C$601&Expense!$D$2:$D$601&Expense!$E$2:$E$601,Expense!$H$2:$H$601,"")} -> 200 | L22: =I22-H22 -> 3258 | M22: =Master_Table[[#This Row],[Expense Budget]]-Master_Table[[#This Row],[Actual Expense]] -> 400 | N22: =I22-K22 -> 6058 | O22: =H22-J22 -> 2400 | P22: =N22-O22 -> 3658 | Q22: =Master_Table[[#This Row],[△Sales Variance]]/Master_Table[[#This Row],[Sales Budget]] -> 1.086 | R22: =Master_Table[[#This Row],[△Expense Variance]]/Master_Table[[#This Row],[Expense Budget]] -> 0.66666667 | S22: =Master_Table[[#This Row],[Net Profit Variance]]/Master_Table[[#This Row],[Budget Net Profit]] -> 1.5241667 | T22: =Master_Table[[#This Row],[Actual Net Profit]]/Master_Table[[#This Row],[Actual Sales]] -> 0.96804091 | U22: =_xlfn.TEXTJOIN(" - ", TRUE, Master_Table[[#This Row],[Product]], Master_Table[[#This Row],[Branch]]) -> Mango - Abuja
A23: 22 | B23: 100 | C23: =VLOOKUP(B23,Products!A:C,2,FALSE) -> Mango | D23: Abuja | E23: =_xlfn.XLOOKUP(D23,'Sales Manager'!$A$2:$A$6,'Sales Manager'!$B$2:$B$6,"") -> Emeka Nwosu | F23: =F11 -> 10 | G23: =G11 -> Oct | H23: 10000 | I23: 7226 | J23: {=_xlfn.XLOOKUP(C23&D23&F23,Expense!$C$2:$C$601&Expense!$D$2:$D$601&Expense!$E$2:$E$601,Expense!$G$2:$G$601,"")} -> 3333.3333 | K23: {=_xlfn.XLOOKUP(C23&D23&F23,Expense!$C$2:$C$601&Expense!$D$2:$D$601&Expense!$E$2:$E$601,Expense!$H$2:$H$601,"")} -> 2933.3333 | L23: =I23-H23 -> -2774 | M23: =Master_Table[[#This Row],[Expense Budget]]-Master_Table[[#This Row],[Actual Expense]] -> 400 | N23: =I23-K23 -> 4292.6667 | O23: =H23-J23 -> 6666.6667 | P23: =N23-O23 -> -2374 | Q23: =Master_Table[[#This Row],[△Sales Variance]]/Master_Table[[#This Row],[Sales Budget]] -> -0.2774 | R23: =Master_Table[[#This Row],[△Expense Variance]]/Master_Table[[#This Row],[Expense Budget]] -> 0.12 | S23: =Master_Table[[#This Row],[Net Profit Variance]]/Master_Table[[#This Row],[Budget Net Profit]] -> -0.3561 | T23: =Master_Table[[#This Row],[Actual Net Profit]]/Master_Table[[#This Row],[Actual Sales]] -> 0.59405849 | U23: =_xlfn.TEXTJOIN(" - ", TRUE, Master_Table[[#This Row],[Product]], Master_Table[[#This Row],[Branch]]) -> Mango - Abuja
A24: 23 | B24: 100 | C24: =VLOOKUP(B24,Products!A:C,2,FALSE) -> Mango | D24: Abuja | E24: =_xlfn.XLOOKUP(D24,'Sales Manager'!$A$2:$A$6,'Sales Manager'!$B$2:$B$6,"") -> Emeka Nwosu | F24: =F12 -> 11 | G24: =G12 -> Nov | H24: 3000 | I24: 3828 | J24: {=_xlfn.XLOOKUP(C24&D24&F24,Expense!$C$2:$C$601&Expense!$D$2:$D$601&Expense!$E$2:$E$601,Expense!$G$2:$G$601,"")} -> 1000 | K24: {=_xlfn.XLOOKUP(C24&D24&F24,Expense!$C$2:$C$601&Expense!$D$2:$D$601&Expense!$E$2:$E$601,Expense!$H$2:$H$601,"")} -> 500 | L24: =I24-H24 -> 828 | M24: =Master_Table[[#This Row],[Expense Budget]]-Master_Table[[#This Row],[Actual Expense]] -> 500 | N24: =I24-K24 -> 3328 | O24: =H24-J24 -> 2000 | P24: =N24-O24 -> 1328 | Q24: =Master_Table[[#This Row],[△Sales Variance]]/Master_Table[[#This Row],[Sales Budget]] -> 0.276 | R24: =Master_Table[[#This Row],[△Expense Variance]]/Master_Table[[#This Row],[Expense Budget]] -> 0.5 | S24: =Master_Table[[#This Row],[Net Profit Variance]]/Master_Table[[#This Row],[Budget Net Profit]] -> 0.664 | T24: =Master_Table[[#This Row],[Actual Net Profit]]/Master_Table[[#This Row],[Actual Sales]] -> 0.86938349 | U24: =_xlfn.TEXTJOIN(" - ", TRUE, Master_Table[[#This Row],[Product]], Master_Table[[#This Row],[Branch]]) -> Mango - Abuja
A25: 24 | B25: 100 | C25: =VLOOKUP(B25,Products!A:C,2,FALSE) -> Mango | D25: Abuja | E25: =_xlfn.XLOOKUP(D25,'Sales Manager'!$A$2:$A$6,'Sales Manager'!$B$2:$B$6,"") -> Emeka Nwosu | F25: =F13 -> 12 | G25: =G13 -> Dec | H25: 3000 | I25: 8161 | J25: {=_xlfn.XLOOKUP(C25&D25&F25,Expense!$C$2:$C$601&Expense!$D$2:$D$601&Expense!$E$2:$E$601,Expense!$G$2:$G$601,"")} -> 1500 | K25: {=_xlfn.XLOOKUP(C25&D25&F25,Expense!$C$2:$C$601&Expense!$D$2:$D$601&Expense!$E$2:$E$601,Expense!$H$2:$H$601,"")} -> 900 | L25: =I25-H25 -> 5161 | M25: =Master_Table[[#This Row],[Expense Budget]]-Master_Table[[#This Row],[Actual Expense]] -> 600 | N25: =I25-K25 -> 7261 | O25: =H25-J25 -> 1500 | P25: =N25-O25 -> 5761 | Q25: =Master_Table[[#This Row],[△Sales Variance]]/Master_Table[[#This Row],[Sales Budget]] -> 1.7203333 | R25: =Master_Table[[#This Row],[△Expense Variance]]/Master_Table[[#This Row],[Expense Budget]] -> 0.4 | S25: =Master_Table[[#This Row],[Net Profit Variance]]/Master_Table[[#This Row],[Budget Net Profit]] -> 3.8406667 | T25: =Master_Table[[#This Row],[Actual Net Profit]]/Master_Table[[#This Row],[Actual Sales]] -> 0.8897194 | U25: =_xlfn.TEXTJOIN(" - ", TRUE, Master_Table[[#This Row],[Product]], Master_Table[[#This Row],[Branch]]) -> Mango - Abuja
... A61: 60 | B61: 100 | C61: =VLOOKUP(B61,Products!A:C,2,FALSE) -> Mango | D61: Ibadan | E61: =_xlfn.XLOOKUP(D61,'Sales Manager'!$A$2:$A$6,'Sales Manager'!$B$2:$B$6,"") -> Funmi Adeyemi | F61: =F49 -> 12 | G61: =G49 -> Dec | H61: 7000 | I61: 2174 | J61: {=_xlfn.XLOOKUP(C61&D61&F61,Expense!$C$2:$C$601&Expense!$D$2:$D$601&Expense!$E$2:$E$601,Expense!$G$2:$G$601,"")} -> 1400 | K61: {=_xlfn.XLOOKUP(C61&D61&F61,Expense!$C$2:$C$601&Expense!$D$2:$D$601&Expense!$E$2:$E$601,Expense!$H$2:$H$601,"")} -> 1400 | L61: =I61-H61 -> -4826 | M61: =Master_Table[[#This Row],[Expense Budget]]-Master_Table[[#This Row],[Actual Expense]] -> 0 | N61: =I61-K61 -> 774 | O61: =H61-J61 -> 5600 | P61: =N61-O61 -> -4826 | Q61: =Master_Table[[#This Row],[△Sales Variance]]/Master_Table[[#This Row],[Sales Budget]] -> -0.68942857 | R61: =Master_Table[[#This Row],[△Expense Variance]]/Master_Table[[#This Row],[Expense Budget]] -> 0 | S61: =Master_Table[[#This Row],[Net Profit Variance]]/Master_Table[[#This Row],[Budget Net Profit]] -> -0.86178571 | T61: =Master_Table[[#This Row],[Actual Net Profit]]/Master_Table[[#This Row],[Actual Sales]] -> 0.35602576 | U61: =_xlfn.TEXTJOIN(" - ", TRUE, Master_Table[[#This Row],[Product]], Master_Table[[#This Row],[Branch]]) -> Mango - Ibadan
A62: 61 | B62: =B2+1 -> 101 | C62: =VLOOKUP(B62,Products!A:C,2,FALSE) -> Orange | D62: =D2 -> Lagos | E62: =_xlfn.XLOOKUP(D62,'Sales Manager'!$A$2:$A$6,'Sales Manager'!$B$2:$B$6,"") -> Adaora Okafor | F62: =F50 -> 1 | G62: =G50 -> Jan | H62: 8000 | I62: 10325 | J62: {=_xlfn.XLOOKUP(C62&D62&F62,Expense!$C$2:$C$601&Expense!$D$2:$D$601&Expense!$E$2:$E$601,Expense!$G$2:$G$601,"")} -> 1600 | K62: {=_xlfn.XLOOKUP(C62&D62&F62,Expense!$C$2:$C$601&Expense!$D$2:$D$601&Expense!$E$2:$E$601,Expense!$H$2:$H$601,"")} -> 1100 | L62: =I62-H62 -> 2325 | M62: =Master_Table[[#This Row],[Expense Budget]]-Master_Table[[#This Row],[Actual Expense]] -> 500 | N62: =I62-K62 -> 9225 | O62: =H62-J62 -> 6400 | P62: =N62-O62 -> 2825 | Q62: =Master_Table[[#This Row],[△Sales Variance]]/Master_Table[[#This Row],[Sales Budget]] -> 0.290625 | R62: =Master_Table[[#This Row],[△Expense Variance]]/Master_Table[[#This Row],[Expense Budget]] -> 0.3125 | S62: =Master_Table[[#This Row],[Net Profit Variance]]/Master_Table[[#This Row],[Budget Net Profit]] -> 0.44140625 | T62: =Master_Table[[#This Row],[Actual Net Profit]]/Master_Table[[#This Row],[Actual Sales]] -> 0.89346247 | U62: =_xlfn.TEXTJOIN(" - ", TRUE, Master_Table[[#This Row],[Product]], Master_Table[[#This Row],[Branch]]) -> Orange - Lagos
A63: 62 | B63: =B3+1 -> 101 | C63: =VLOOKUP(B63,Products!A:C,2,FALSE) -> Orange | D63: =D3 -> Lagos | E63: =_xlfn.XLOOKUP(D63,'Sales Manager'!$A$2:$A$6,'Sales Manager'!$B$2:$B$6,"") -> Adaora Okafor | F63: =F51 -> 2 | G63: =G51 -> Feb | H63: 5000 | I63: 5222 | J63: {=_xlfn.XLOOKUP(C63&D63&F63,Expense!$C$2:$C$601&Expense!$D$2:$D$601&Expense!$E$2:$E$601,Expense!$G$2:$G$601,"")} -> 1000 | K63: {=_xlfn.XLOOKUP(C63&D63&F63,Expense!$C$2:$C$601&Expense!$D$2:$D$601&Expense!$E$2:$E$601,Expense!$H$2:$H$601,"")} -> 800 | L63: =I63-H63 -> 222 | M63: =Master_Table[[#This Row],[Expense Budget]]-Master_Table[[#This Row],[Actual Expense]] -> 200 | N63: =I63-K63 -> 4422 | O63: =H63-J63 -> 4000 | P63: =N63-O63 -> 422 | Q63: =Master_Table[[#This Row],[△Sales Variance]]/Master_Table[[#This Row],[Sales Budget]] -> 0.0444 | R63: =Master_Table[[#This Row],[△Expense Variance]]/Master_Table[[#This Row],[Expense Budget]] -> 0.2 | S63: =Master_Table[[#This Row],[Net Profit Variance]]/Master_Table[[#This Row],[Budget Net Profit]] -> 0.1055 | T63: =Master_Table[[#This Row],[Actual Net Profit]]/Master_Table[[#This Row],[Actual Sales]] -> 0.84680199 | U63: =_xlfn.TEXTJOIN(" - ", TRUE, Master_Table[[#This Row],[Product]], Master_Table[[#This Row],[Branch]]) -> Orange - Lagos
A64: 63 | B64: =B4+1 -> 101 | C64: =VLOOKUP(B64,Products!A:C,2,FALSE) -> Orange | D64: =D4 -> Lagos | E64: =_xlfn.XLOOKUP(D64,'Sales Manager'!$A$2:$A$6,'Sales Manager'!$B$2:$B$6,"") -> Adaora Okafor | F64: =F52 -> 3 | G64: =G52 -> Mar | H64: 2000 | I64: 2139 | J64: {=_xlfn.XLOOKUP(C64&D64&F64,Expense!$C$2:$C$601&Expense!$D$2:$D$601&Expense!$E$2:$E$601,Expense!$G$2:$G$601,"")} -> 1000 | K64: {=_xlfn.XLOOKUP(C64&D64&F64,Expense!$C$2:$C$601&Expense!$D$2:$D$601&Expense!$E$2:$E$601,Expense!$H$2:$H$601,"")} -> 600 | L64: =I64-H64 -> 139 | M64: =Master_Table[[#This Row],[Expense Budget]]-Master_Table[[#This Row],[Actual Expense]] -> 400 | N64: =I64-K64 -> 1539 | O64: =H64-J64 -> 1000 | P64: =N64-O64 -> 539 | Q64: =Master_Table[[#This Row],[△Sales Variance]]/Master_Table[[#This Row],[Sales Budget]] -> 0.0695 | R64: =Master_Table[[#This Row],[△Expense Variance]]/Master_Table[[#This Row],[Expense Budget]] -> 0.4 | S64: =Master_Table[[#This Row],[Net Profit Variance]]/Master_Table[[#This Row],[Budget Net Profit]] -> 0.539 | T64: =Master_Table[[#This Row],[Actual Net Profit]]/Master_Table[[#This Row],[Actual Sales]] -> 0.71949509 | U64: =_xlfn.TEXTJOIN(" - ", TRUE, Master_Table[[#This Row],[Product]], Master_Table[[#This Row],[Branch]]) -> Orange - Lagos
A65: 64 | B65: =B5+1 -> 101 | C65: =VLOOKUP(B65,Products!A:C,2,FALSE) -> Orange | D65: =D5 -> Lagos | E65: =_xlfn.XLOOKUP(D65,'Sales Manager'!$A$2:$A$6,'Sales Manager'!$B$2:$B$6,"") -> Adaora Okafor | F65: =F53 -> 4 | G65: =G53 -> Apr | H65: 6000 | I65: 3859 | J65: {=_xlfn.XLOOKUP(C65&D65&F65,Expense!$C$2:$C$601&Expense!$D$2:$D$601&Expense!$E$2:$E$601,Expense!$G$2:$G$601,"")} -> 1200 | K65: {=_xlfn.XLOOKUP(C65&D65&F65,Expense!$C$2:$C$601&Expense!$D$2:$D$601&Expense!$E$2:$E$601,Expense!$H$2:$H$601,"")} -> 1200 | L65: =I65-H65 -> -2141 | M65: =Master_Table[[#This Row],[Expense Budget]]-Master_Table[[#This Row],[Actual Expense]] -> 0 | N65: =I65-K65 -> 2659 | O65: =H65-J65 -> 4800 | P65: =N65-O65 -> -2141 | Q65: =Master_Table[[#This Row],[△Sales Variance]]/Master_Table[[#This Row],[Sales Budget]] -> -0.35683333 | R65: =Master_Table[[#This Row],[△Expense Variance]]/Master_Table[[#This Row],[Expense Budget]] -> 0 | S65: =Master_Table[[#This Row],[Net Profit Variance]]/Master_Table[[#This Row],[Budget Net Profit]] -> -0.44604167 | T65: =Master_Table[[#This Row],[Actual Net Profit]]/Master_Table[[#This Row],[Actual Sales]] -> 0.68903861 | U65: =_xlfn.TEXTJOIN(" - ", TRUE, Master_Table[[#This Row],[Product]], Master_Table[[#This Row],[Branch]]) -> Orange - Lagos
A66: 65 | B66: =B6+1 -> 101 | C66: =VLOOKUP(B66,Products!A:C,2,FALSE) -> Orange | D66: =D6 -> Lagos | E66: =_xlfn.XLOOKUP(D66,'Sales Manager'!$A$2:$A$6,'Sales Manager'!$B$2:$B$6,"") -> Adaora Okafor | F66: =F54 -> 5 | G66: =G54 -> May | H66: 1000 | I66: 2236 | J66: {=_xlfn.XLOOKUP(C66&D66&F66,Expense!$C$2:$C$601&Expense!$D$2:$D$601&Expense!$E$2:$E$601,Expense!$G$2:$G$601,"")} -> 333.33333 | K66: {=_xlfn.XLOOKUP(C66&D66&F66,Expense!$C$2:$C$601&Expense!$D$2:$D$601&Expense!$E$2:$E$601,Expense!$H$2:$H$601,"")} -> 766.66667 | L66: =I66-H66 -> 1236 | M66: =Master_Table[[#This Row],[Expense Budget]]-Master_Table[[#This Row],[Actual Expense]] -> -433.33333 | N66: =I66-K66 -> 1469.3333 | O66: =H66-J66 -> 666.66667 | P66: =N66-O66 -> 802.66667 | Q66: =Master_Table[[#This Row],[△Sales Variance]]/Master_Table[[#This Row],[Sales Budget]] -> 1.236 | R66: =Master_Table[[#This Row],[△Expense Variance]]/Master_Table[[#This Row],[Expense Budget]] -> -1.3 | S66: =Master_Table[[#This Row],[Net Profit Variance]]/Master_Table[[#This Row],[Budget Net Profit]] -> 1.204 | T66: =Master_Table[[#This Row],[Actual Net Profit]]/Master_Table[[#This Row],[Actual Sales]] -> 0.65712582 | U66: =_xlfn.TEXTJOIN(" - ", TRUE, Master_Table[[#This Row],[Product]], Master_Table[[#This Row],[Branch]]) -> Orange - Lagos
A67: 66 | B67: =B7+1 -> 101 | C67: =VLOOKUP(B67,Products!A:C,2,FALSE) -> Orange | D67: =D7 -> Lagos | E67: =_xlfn.XLOOKUP(D67,'Sales Manager'!$A$2:$A$6,'Sales Manager'!$B$2:$B$6,"") -> Adaora Okafor | F67: =F55 -> 6 | G67: =G55 -> Jun | H67: 1000 | I67: 6353 | J67: {=_xlfn.XLOOKUP(C67&D67&F67,Expense!$C$2:$C$601&Expense!$D$2:$D$601&Expense!$E$2:$E$601,Expense!$G$2:$G$601,"")} -> 333.33333 | K67: {=_xlfn.XLOOKUP(C67&D67&F67,Expense!$C$2:$C$601&Expense!$D$2:$D$601&Expense!$E$2:$E$601,Expense!$H$2:$H$601,"")} -> 133.33333 | L67: =I67-H67 -> 5353 | M67: =Master_Table[[#This Row],[Expense Budget]]-Master_Table[[#This Row],[Actual Expense]] -> 200 | N67: =I67-K67 -> 6219.6667 | O67: =H67-J67 -> 666.66667 | P67: =N67-O67 -> 5553 | Q67: =Master_Table[[#This Row],[△Sales Variance]]/Master_Table[[#This Row],[Sales Budget]] -> 5.353 | R67: =Master_Table[[#This Row],[△Expense Variance]]/Master_Table[[#This Row],[Expense Budget]] -> 0.6 | S67: =Master_Table[[#This Row],[Net Profit Variance]]/Master_Table[[#This Row],[Budget Net Profit]] -> 8.3295 | T67: =Master_Table[[#This Row],[Actual Net Profit]]/Master_Table[[#This Row],[Actual Sales]] -> 0.97901254 | U67: =_xlfn.TEXTJOIN(" - ", TRUE, Master_Table[[#This Row],[Product]], Master_Table[[#This Row],[Branch]]) -> Orange - Lagos
A68: 67 | B68: =B8+1 -> 101 | C68: =VLOOKUP(B68,Products!A:C,2,FALSE) -> Orange | D68: =D8 -> Lagos | E68: =_xlfn.XLOOKUP(D68,'Sales Manager'!$A$2:$A$6,'Sales Manager'!$B$2:$B$6,"") -> Adaora Okafor | F68: =F56 -> 7 | G68: =G56 -> Jul | H68: 3000 | I68: 5666 | J68: {=_xlfn.XLOOKUP(C68&D68&F68,Expense!$C$2:$C$601&Expense!$D$2:$D$601&Expense!$E$2:$E$601,Expense!$G$2:$G$601,"")} -> 750 | K68: {=_xlfn.XLOOKUP(C68&D68&F68,Expense!$C$2:$C$601&Expense!$D$2:$D$601&Expense!$E$2:$E$601,Expense!$H$2:$H$601,"")} -> 450 | L68: =I68-H68 -> 2666 | M68: =Master_Table[[#This Row],[Expense Budget]]-Master_Table[[#This Row],[Actual Expense]] -> 300 | N68: =I68-K68 -> 5216 | O68: =H68-J68 -> 2250 | P68: =N68-O68 -> 2966 | Q68: =Master_Table[[#This Row],[△Sales Variance]]/Master_Table[[#This Row],[Sales Budget]] -> 0.88866667 | R68: =Master_Table[[#This Row],[△Expense Variance]]/Master_Table[[#This Row],[Expense Budget]] -> 0.4 | S68: =Master_Table[[#This Row],[Net Profit Variance]]/Master_Table[[#This Row],[Budget Net Profit]] -> 1.3182222 | T68: =Master_Table[[#This Row],[Actual Net Profit]]/Master_Table[[#This Row],[Actual Sales]] -> 0.92057889 | U68: =_xlfn.TEXTJOIN(" - ", TRUE, Master_Table[[#This Row],[Product]], Master_Table[[#This Row],[Branch]]) -> Orange - Lagos
A69: 68 | B69: =B9+1 -> 101 | C69: =VLOOKUP(B69,Products!A:C,2,FALSE) -> Orange | D69: =D9 -> Lagos | E69: =_xlfn.XLOOKUP(D69,'Sales Manager'!$A$2:$A$6,'Sales Manager'!$B$2:$B$6,"") -> Adaora Okafor | F69: =F57 -> 8 | G69: =G57 -> Aug | H69: 8000 | I69: 9444 | J69: {=_xlfn.XLOOKUP(C69&D69&F69,Expense!$C$2:$C$601&Expense!$D$2:$D$601&Expense!$E$2:$E$601,Expense!$G$2:$G$601,"")} -> 2666.6667 | K69: {=_xlfn.XLOOKUP(C69&D69&F69,Expense!$C$2:$C$601&Expense!$D$2:$D$601&Expense!$E$2:$E$601,Expense!$H$2:$H$601,"")} -> 2566.6667 | L69: =I69-H69 -> 1444 | M69: =Master_Table[[#This Row],[Expense Budget]]-Master_Table[[#This Row],[Actual Expense]] -> 100 | N69: =I69-K69 -> 6877.3333 | O69: =H69-J69 -> 5333.3333 | P69: =N69-O69 -> 1544 | Q69: =Master_Table[[#This Row],[△Sales Variance]]/Master_Table[[#This Row],[Sales Budget]] -> 0.1805 | R69: =Master_Table[[#This Row],[△Expense Variance]]/Master_Table[[#This Row],[Expense Budget]] -> 0.0375 | S69: =Master_Table[[#This Row],[Net Profit Variance]]/Master_Table[[#This Row],[Budget Net Profit]] -> 0.2895 | T69: =Master_Table[[#This Row],[Actual Net Profit]]/Master_Table[[#This Row],[Actual Sales]] -> 0.7282225 | U69: =_xlfn.TEXTJOIN(" - ", TRUE, Master_Table[[#This Row],[Product]], Master_Table[[#This Row],[Branch]]) -> Orange - Lagos
A70: 69 | B70: =B10+1 -> 101 | C70: =VLOOKUP(B70,Products!A:C,2,FALSE) -> Orange | D70: =D10 -> Lagos | E70: =_xlfn.XLOOKUP(D70,'Sales Manager'!$A$2:$A$6,'Sales Manager'!$B$2:$B$6,"") -> Adaora Okafor | F70: =F58 -> 9 | G70: =G58 -> Sept | H70: 2000 | I70: 4831 | J70: {=_xlfn.XLOOKUP(C70&D70&F70,Expense!$C$2:$C$601&Expense!$D$2:$D$601&Expense!$E$2:$E$601,Expense!$G$2:$G$601,"")} -> 1000 | K70: {=_xlfn.XLOOKUP(C70&D70&F70,Expense!$C$2:$C$601&Expense!$D$2:$D$601&Expense!$E$2:$E$601,Expense!$H$2:$H$601,"")} -> 700 | L70: =I70-H70 -> 2831 | M70: =Master_Table[[#This Row],[Expense Budget]]-Master_Table[[#This Row],[Actual Expense]] -> 300 | N70: =I70-K70 -> 4131 | O70: =H70-J70 -> 1000 | P70: =N70-O70 -> 3131 | Q70: =Master_Table[[#This Row],[△Sales Variance]]/Master_Table[[#This Row],[Sales Budget]] -> 1.4155 | R70: =Master_Table[[#This Row],[△Expense Variance]]/Master_Table[[#This Row],[Expense Budget]] -> 0.3 | S70: =Master_Table[[#This Row],[Net Profit Variance]]/Master_Table[[#This Row],[Budget Net Profit]] -> 3.131 | T70: =Master_Table[[#This Row],[Actual Net Profit]]/Master_Table[[#This Row],[Actual Sales]] -> 0.85510246 | U70: =_xlfn.TEXTJOIN(" - ", TRUE, Master_Table[[#This Row],[Product]], Master_Table[[#This Row],[Branch]]) -> Orange - Lagos
A71: 70 | B71: =B11+1 -> 101 | C71: =VLOOKUP(B71,Products!A:C,2,FALSE) -> Orange | D71: =D11 -> Lagos | E71: =_xlfn.XLOOKUP(D71,'Sales Manager'!$A$2:$A$6,'Sales Manager'!$B$2:$B$6,"") -> Adaora Okafor | F71: =F59 -> 10 | G71: =G59 -> Oct | H71: 6000 | I71: 8644 | J71: {=_xlfn.XLOOKUP(C71&D71&F71,Expense!$C$2:$C$601&Expense!$D$2:$D$601&Expense!$E$2:$E$601,Expense!$G$2:$G$601,"")} -> 1500 | K71: {=_xlfn.XLOOKUP(C71&D71&F71,Expense!$C$2:$C$601&Expense!$D$2:$D$601&Expense!$E$2:$E$601,Expense!$H$2:$H$601,"")} -> 1400 | L71: =I71-H71 -> 2644 | M71: =Master_Table[[#This Row],[Expense Budget]]-Master_Table[[#This Row],[Actual Expense]] -> 100 | N71: =I71-K71 -> 7244 | O71: =H71-J71 -> 4500 | P71: =N71-O71 -> 2744 | Q71: =Master_Table[[#This Row],[△Sales Variance]]/Master_Table[[#This Row],[Sales Budget]] -> 0.44066667 | R71: =Master_Table[[#This Row],[△Expense Variance]]/Master_Table[[#This Row],[Expense Budget]] -> 0.066666667 | S71: =Master_Table[[#This Row],[Net Profit Variance]]/Master_Table[[#This Row],[Budget Net Profit]] -> 0.60977778 | T71: =Master_Table[[#This Row],[Actual Net Profit]]/Master_Table[[#This Row],[Actual Sales]] -> 0.83803795 | U71: =_xlfn.TEXTJOIN(" - ", TRUE, Master_Table[[#This Row],[Product]], Master_Table[[#This Row],[Branch]]) -> Orange - Lagos
A72: 71 | B72: =B12+1 -> 101 | C72: =VLOOKUP(B72,Products!A:C,2,FALSE) -> Orange | D72: =D12 -> Lagos | E72: =_xlfn.XLOOKUP(D72,'Sales Manager'!$A$2:$A$6,'Sales Manager'!$B$2:$B$6,"") -> Adaora Okafor | F72: =F60 -> 11 | G72: =G60 -> Nov | H72: 4000 | I72: 3826 | J72: {=_xlfn.XLOOKUP(C72&D72&F72,Expense!$C$2:$C$601&Expense!$D$2:$D$601&Expense!$E$2:$E$601,Expense!$G$2:$G$601,"")} -> 1333.3333 | K72: {=_xlfn.XLOOKUP(C72&D72&F72,Expense!$C$2:$C$601&Expense!$D$2:$D$601&Expense!$E$2:$E$601,Expense!$H$2:$H$601,"")} -> 1233.3333 | L72: =I72-H72 -> -174 | M72: =Master_Table[[#This Row],[Expense Budget]]-Master_Table[[#This Row],[Actual Expense]] -> 100 | N72: =I72-K72 -> 2592.6667 | O72: =H72-J72 -> 2666.6667 | P72: =N72-O72 -> -74 | Q72: =Master_Table[[#This Row],[△Sales Variance]]/Master_Table[[#This Row],[Sales Budget]] -> -0.0435 | R72: =Master_Table[[#This Row],[△Expense Variance]]/Master_Table[[#This Row],[Expense Budget]] -> 0.075 | S72: =Master_Table[[#This Row],[Net Profit Variance]]/Master_Table[[#This Row],[Budget Net Profit]] -> -0.02775 | T72: =Master_Table[[#This Row],[Actual Net Profit]]/Master_Table[[#This Row],[Actual Sales]] -> 0.67764419 | U72: =_xlfn.TEXTJOIN(" - ", TRUE, Master_Table[[#This Row],[Product]], Master_Table[[#This Row],[Branch]]) -> Orange - Lagos
A73: 72 | B73: =B13+1 -> 101 | C73: =VLOOKUP(B73,Products!A:C,2,FALSE) -> Orange | D73: =D13 -> Lagos | E73: =_xlfn.XLOOKUP(D73,'Sales Manager'!$A$2:$A$6,'Sales Manager'!$B$2:$B$6,"") -> Adaora Okafor | F73: =F61 -> 12 | G73: =G61 -> Dec | H73: 4000 | I73: 2454 | J73: {=_xlfn.XLOOKUP(C73&D73&F73,Expense!$C$2:$C$601&Expense!$D$2:$D$601&Expense!$E$2:$E$601,Expense!$G$2:$G$601,"")} -> 800 | K73: {=_xlfn.XLOOKUP(C73&D73&F73,Expense!$C$2:$C$601&Expense!$D$2:$D$601&Expense!$E$2:$E$601,Expense!$H$2:$H$601,"")} -> 600 | L73: =I73-H73 -> -1546 | M73: =Master_Table[[#This Row],[Expense Budget]]-Master_Table[[#This Row],[Actual Expense]] -> 200 | N73: =I73-K73 -> 1854 | O73: =H73-J73 -> 3200 | P73: =N73-O73 -> -1346 | Q73: =Master_Table[[#This Row],[△Sales Variance]]/Master_Table[[#This Row],[Sales Budget]] -> -0.3865 | R73: =Master_Table[[#This Row],[△Expense Variance]]/Master_Table[[#This Row],[Expense Budget]] -> 0.25 | S73: =Master_Table[[#This Row],[Net Profit Variance]]/Master_Table[[#This Row],[Budget Net Profit]] -> -0.420625 | T73: =Master_Table[[#This Row],[Actual Net Profit]]/Master_Table[[#This Row],[Actual Sales]] -> 0.75550122 | U73: =_xlfn.TEXTJOIN(" - ", TRUE, Master_Table[[#This Row],[Product]], Master_Table[[#This Row],[Branch]]) -> Orange - Lagos
... A601: 600 | B601: =B541+1 -> 109 | C601: =VLOOKUP(B601,Products!A:C,2,FALSE) -> Pawpaw | D601: =D541 -> Ibadan | E601: =_xlfn.XLOOKUP(D601,'Sales Manager'!$A$2:$A$6,'Sales Manager'!$B$2:$B$6,"") -> Funmi Adeyemi | F601: =F589 -> 12 | G601: =G589 -> Dec | H601: 6000 | I601: 4561 | J601: {=_xlfn.XLOOKUP(C601&D601&F601,Expense!$C$2:$C$601&Expense!$D$2:$D$601&Expense!$E$2:$E$601,Expense!$G$2:$G$601,"")} -> 2000 | K601: {=_xlfn.XLOOKUP(C601&D601&F601,Expense!$C$2:$C$601&Expense!$D$2:$D$601&Expense!$E$2:$E$601,Expense!$H$2:$H$601,"")} -> 1800 | L601: =I601-H601 -> -1439 | M601: =Master_Table[[#This Row],[Expense Budget]]-Master_Table[[#This Row],[Actual Expense]] -> 200 | N601: =I601-K601 -> 2761 | O601: =H601-J601 -> 4000 | P601: =N601-O601 -> -1239 | Q601: =Master_Table[[#This Row],[△Sales Variance]]/Master_Table[[#This Row],[Sales Budget]] -> -0.23983333 | R601: =Master_Table[[#This Row],[△Expense Variance]]/Master_Table[[#This Row],[Expense Budget]] -> 0.1 | S601: =Master_Table[[#This Row],[Net Profit Variance]]/Master_Table[[#This Row],[Budget Net Profit]] -> -0.30975 | T601: =Master_Table[[#This Row],[Actual Net Profit]]/Master_Table[[#This Row],[Actual Sales]] -> 0.6053497 | U601: =_xlfn.TEXTJOIN(" - ", TRUE, Master_Table[[#This Row],[Product]], Master_Table[[#This Row],[Branch]]) -> Pawpaw - Ibadan

Sheet Expense
A1: SN | B1: ProdCode | C1: Product | D1: Branch | E1: MonthCode | F1: Month | G1: Expense Budget | H1: Actual Expense | I1: Branch Manager
A2: 1 | B2: 100 | C2: =VLOOKUP(B2,Products!A:C,2,FALSE) -> Mango | D2: Lagos | E2: 1 | F2: Jan | G2: 500 | H2: 500 | I2: =_xlfn.XLOOKUP(D2,'Sales Manager'!$A$2:$A$6,'Sales Manager'!$B$2:$B$6,"") -> Adaora Okafor | J2: 9 | K2: 9
A3: 2 | B3: 100 | C3: =VLOOKUP(B3,Products!A:C,2,FALSE) -> Mango | D3: Lagos | E3: 2 | F3: Feb | G3: 600 | H3: 500 | I3: =_xlfn.XLOOKUP(D3,'Sales Manager'!$A$2:$A$6,'Sales Manager'!$B$2:$B$6,"") -> Adaora Okafor | J3: 10 | K3: 9
A4: 3 | B4: 100 | C4: =VLOOKUP(B4,Products!A:C,2,FALSE) -> Mango | D4: Lagos | E4: 3 | F4: Mar | G4: 2500 | H4: 2200 | I4: =_xlfn.XLOOKUP(D4,'Sales Manager'!$A$2:$A$6,'Sales Manager'!$B$2:$B$6,"") -> Adaora Okafor | J4: 5 | K4: 5
A5: 4 | B5: 100 | C5: =VLOOKUP(B5,Products!A:C,2,FALSE) -> Mango | D5: Lagos | E5: 4 | F5: Apr | G5: 1750 | H5: 1350 | I5: =_xlfn.XLOOKUP(D5,'Sales Manager'!$A$2:$A$6,'Sales Manager'!$B$2:$B$6,"") -> Adaora Okafor | J5: 9 | K5: 7
A6: 5 | B6: 100 | C6: =VLOOKUP(B6,Products!A:C,2,FALSE) -> Mango | D6: Lagos | E6: 5 | F6: May | G6: 1000 | H6: 600 | I6: =_xlfn.XLOOKUP(D6,'Sales Manager'!$A$2:$A$6,'Sales Manager'!$B$2:$B$6,"") -> Adaora Okafor | J6: 9 | K6: 10
A7: 6 | B7: 100 | C7: =VLOOKUP(B7,Products!A:C,2,FALSE) -> Mango | D7: Lagos | E7: 6 | F7: Jun | G7: 1400 | H7: 1300 | I7: =_xlfn.XLOOKUP(D7,'Sales Manager'!$A$2:$A$6,'Sales Manager'!$B$2:$B$6,"") -> Adaora Okafor | J7: 9 | K7: 10
A8: 7 | B8: 100 | C8: =VLOOKUP(B8,Products!A:C,2,FALSE) -> Mango | D8: Lagos | E8: 7 | F8: Jul | G8: 2500 | H8: 2400 | I8: =_xlfn.XLOOKUP(D8,'Sales Manager'!$A$2:$A$6,'Sales Manager'!$B$2:$B$6,"") -> Adaora Okafor | J8: 10 | K8: 5
A9: 8 | B9: 100 | C9: =VLOOKUP(B9,Products!A:C,2,FALSE) -> Mango | D9: Lagos | E9: 8 | F9: Aug | G9: 333.33333 | H9: 266.66667 | I9: =_xlfn.XLOOKUP(D9,'Sales Manager'!$A$2:$A$6,'Sales Manager'!$B$2:$B$6,"") -> Adaora Okafor | J9: 8 | K9: 5
A10: 9 | B10: 100 | C10: =VLOOKUP(B10,Products!A:C,2,FALSE) -> Mango | D10: Lagos | E10: 9 | F10: Sept | G10: 1600 | H10: 1400 | I10: =_xlfn.XLOOKUP(D10,'Sales Manager'!$A$2:$A$6,'Sales Manager'!$B$2:$B$6,"") -> Adaora Okafor | J10: 5 | K10: 5
A11: 10 | B11: 100 | C11: =VLOOKUP(B11,Products!A:C,2,FALSE) -> Mango | D11: Lagos | E11: 10 | F11: Oct | G11: 1400 | H11: 1000 | I11: =_xlfn.XLOOKUP(D11,'Sales Manager'!$A$2:$A$6,'Sales Manager'!$B$2:$B$6,"") -> Adaora Okafor | J11: 8 | K11: 6
A12: 11 | B12: 100 | C12: =VLOOKUP(B12,Products!A:C,2,FALSE) -> Mango | D12: Lagos | E12: 11 | F12: Nov | G12: 666.66667 | H12: 333.33333 | I12: =_xlfn.XLOOKUP(D12,'Sales Manager'!$A$2:$A$6,'Sales Manager'!$B$2:$B$6,"") -> Adaora Okafor | J12: 9 | K12: 9
A13: 12 | B13: 100 | C13: =VLOOKUP(B13,Products!A:C,2,FALSE) -> Mango | D13: Lagos | E13: 12 | F13: Dec | G13: 400 | H13: 400 | I13: =_xlfn.XLOOKUP(D13,'Sales Manager'!$A$2:$A$6,'Sales Manager'!$B$2:$B$6,"") -> Adaora Okafor | J13: 9 | K13: 7
A14: 13 | B14: 100 | C14: =VLOOKUP(B14,Products!A:C,2,FALSE) -> Mango | D14: Abuja | E14: =E2 -> 1 | F14: =F2 -> Jan | G14: 2500 | H14: 2400 | I14: =_xlfn.XLOOKUP(D14,'Sales Manager'!$A$2:$A$6,'Sales Manager'!$B$2:$B$6,"") -> Emeka Nwosu | J14: 9 | K14: 5
A15: 14 | B15: 100 | C15: =VLOOKUP(B15,Products!A:C,2,FALSE) -> Mango | D15: Abuja | E15: =E3 -> 2 | F15: =F3 -> Feb | G15: 400 | H15: 500 | I15: =_xlfn.XLOOKUP(D15,'Sales Manager'!$A$2:$A$6,'Sales Manager'!$B$2:$B$6,"") -> Emeka Nwosu | J15: 9 | K15: 8
A16: 15 | B16: 100 | C16: =VLOOKUP(B16,Products!A:C,2,FALSE) -> Mango | D16: Abuja | E16: =E4 -> 3 | F16: =F4 -> Mar | G16: 250 | H16: 250 | I16: =_xlfn.XLOOKUP(D16,'Sales Manager'!$A$2:$A$6,'Sales Manager'!$B$2:$B$6,"") -> Emeka Nwosu | J16: 7 | K16: 9
A17: 16 | B17: 100 | C17: =VLOOKUP(B17,Products!A:C,2,FALSE) -> Mango | D17: Abuja | E17: =E5 -> 4 | F17: =F5 -> Apr | G17: 600 | H17: 600 | I17: =_xlfn.XLOOKUP(D17,'Sales Manager'!$A$2:$A$6,'Sales Manager'!$B$2:$B$6,"") -> Emeka Nwosu | J17: 5 | K17: 6
A18: 17 | B18: 100 | C18: =VLOOKUP(B18,Products!A:C,2,FALSE) -> Mango | D18: Abuja | E18: =E6 -> 5 | F18: =F6 -> May | G18: 2000 | H18: 1800 | I18: =_xlfn.XLOOKUP(D18,'Sales Manager'!$A$2:$A$6,'Sales Manager'!$B$2:$B$6,"") -> Emeka Nwosu | J18: 10 | K18: 7
A19: 18 | B19: 100 | C19: =VLOOKUP(B19,Products!A:C,2,FALSE) -> Mango | D19: Abuja | E19: =E7 -> 6 | F19: =F7 -> Jun | G19: 3500 | H19: 3100 | I19: =_xlfn.XLOOKUP(D19,'Sales Manager'!$A$2:$A$6,'Sales Manager'!$B$2:$B$6,"") -> Emeka Nwosu | J19: 6 | K19: 10
A20: 19 | B20: 100 | C20: =VLOOKUP(B20,Products!A:C,2,FALSE) -> Mango | D20: Abuja | E20: =E8 -> 7 | F20: =F8 -> Jul | G20: 666.66667 | H20: 333.33333 | I20: =_xlfn.XLOOKUP(D20,'Sales Manager'!$A$2:$A$6,'Sales Manager'!$B$2:$B$6,"") -> Emeka Nwosu | J20: 8 | K20: 10
A21: 20 | B21: 100 | C21: =VLOOKUP(B21,Products!A:C,2,FALSE) -> Mango | D21: Abuja | E21: =E9 -> 8 | F21: =F9 -> Aug | G21: 2500 | H21: 1900 | I21: =_xlfn.XLOOKUP(D21,'Sales Manager'!$A$2:$A$6,'Sales Manager'!$B$2:$B$6,"") -> Emeka Nwosu | J21: 6 | K21: 9
A22: 21 | B22: 100 | C22: =VLOOKUP(B22,Products!A:C,2,FALSE) -> Mango | D22: Abuja | E22: =E10 -> 9 | F22: =F10 -> Sept | G22: 600 | H22: 200 | I22: =_xlfn.XLOOKUP(D22,'Sales Manager'!$A$2:$A$6,'Sales Manager'!$B$2:$B$6,"") -> Emeka Nwosu | J22: 8 | K22: 7
A23: 22 | B23: 100 | C23: =VLOOKUP(B23,Products!A:C,2,FALSE) -> Mango | D23: Abuja | E23: =E11 -> 10 | F23: =F11 -> Oct | G23: 3333.3333 | H23: 2933.3333 | I23: =_xlfn.XLOOKUP(D23,'Sales Manager'!$A$2:$A$6,'Sales Manager'!$B$2:$B$6,"") -> Emeka Nwosu | J23: 8 | K23: 5
A24: 23 | B24: 100 | C24: =VLOOKUP(B24,Products!A:C,2,FALSE) -> Mango | D24: Abuja | E24: =E12 -> 11 | F24: =F12 -> Nov | G24: 1000 | H24: 500 | I24: =_xlfn.XLOOKUP(D24,'Sales Manager'!$A$2:$A$6,'Sales Manager'!$B$2:$B$6,"") -> Emeka Nwosu | J24: 6 | K24: 8
A25: 24 | B25: 100 | C25: =VLOOKUP(B25,Products!A:C,2,FALSE) -> Mango | D25: Abuja | E25: =E13 -> 12 | F25: =F13 -> Dec | G25: 1500 | H25: 900 | I25: =_xlfn.XLOOKUP(D25,'Sales Manager'!$A$2:$A$6,'Sales Manager'!$B$2:$B$6,"") -> Emeka Nwosu | J25: 8 | K25: 8
... A61: 60 | B61: 100 | C61: =VLOOKUP(B61,Products!A:C,2,FALSE) -> Mango | D61: Ibadan | E61: =E49 -> 12 | F61: =F49 -> Dec | G61: 1400 | H61: 1400 | I61: =_xlfn.XLOOKUP(D61,'Sales Manager'!$A$2:$A$6,'Sales Manager'!$B$2:$B$6,"") -> Funmi Adeyemi | J61: 7 | K61: 5
A62: 61 | B62: =B2+1 -> 101 | C62: =VLOOKUP(B62,Products!A:C,2,FALSE) -> Orange | D62: =D2 -> Lagos | E62: =E50 -> 1 | F62: =F50 -> Jan | G62: 1600 | H62: 1100 | I62: =_xlfn.XLOOKUP(D62,'Sales Manager'!$A$2:$A$6,'Sales Manager'!$B$2:$B$6,"") -> Adaora Okafor | J62: 5 | K62: 9
A63: 62 | B63: =B3+1 -> 101 | C63: =VLOOKUP(B63,Products!A:C,2,FALSE) -> Orange | D63: =D3 -> Lagos | E63: =E51 -> 2 | F63: =F51 -> Feb | G63: 1000 | H63: 800 | I63: =_xlfn.XLOOKUP(D63,'Sales Manager'!$A$2:$A$6,'Sales Manager'!$B$2:$B$6,"") -> Adaora Okafor | J63: 8 | K63: 6
A64: 63 | B64: =B4+1 -> 101 | C64: =VLOOKUP(B64,Products!A:C,2,FALSE) -> Orange | D64: =D4 -> Lagos | E64: =E52 -> 3 | F64: =F52 -> Mar | G64: 1000 | H64: 600 | I64: =_xlfn.XLOOKUP(D64,'Sales Manager'!$A$2:$A$6,'Sales Manager'!$B$2:$B$6,"") -> Adaora Okafor | J64: 8 | K64: 8
A65: 64 | B65: =B5+1 -> 101 | C65: =VLOOKUP(B65,Products!A:C,2,FALSE) -> Orange | D65: =D5 -> Lagos | E65: =E53 -> 4 | F65: =F53 -> Apr | G65: 1200 | H65: 1200 | I65: =_xlfn.XLOOKUP(D65,'Sales Manager'!$A$2:$A$6,'Sales Manager'!$B$2:$B$6,"") -> Adaora Okafor | J65: 8 | K65: 5
A66: 65 | B66: =B6+1 -> 101 | C66: =VLOOKUP(B66,Products!A:C,2,FALSE) -> Orange | D66: =D6 -> Lagos | E66: =E54 -> 5 | F66: =F54 -> May | G66: 333.33333 | H66: 766.66667 | I66: =_xlfn.XLOOKUP(D66,'Sales Manager'!$A$2:$A$6,'Sales Manager'!$B$2:$B$6,"") -> Adaora Okafor | J66: 5 | K66: 10
A67: 66 | B67: =B7+1 -> 101 | C67: =VLOOKUP(B67,Products!A:C,2,FALSE) -> Orange | D67: =D7 -> Lagos | E67: =E55 -> 6 | F67: =F55 -> Jun | G67: 333.33333 | H67: 133.33333 | I67: =_xlfn.XLOOKUP(D67,'Sales Manager'!$A$2:$A$6,'Sales Manager'!$B$2:$B$6,"") -> Adaora Okafor | J67: 5 | K67: 10
A68: 67 | B68: =B8+1 -> 101 | C68: =VLOOKUP(B68,Products!A:C,2,FALSE) -> Orange | D68: =D8 -> Lagos | E68: =E56 -> 7 | F68: =F56 -> Jul | G68: 750 | H68: 450 | I68: =_xlfn.XLOOKUP(D68,'Sales Manager'!$A$2:$A$6,'Sales Manager'!$B$2:$B$6,"") -> Adaora Okafor | J68: 7 | K68: 7
A69: 68 | B69: =B9+1 -> 101 | C69: =VLOOKUP(B69,Products!A:C,2,FALSE) -> Orange | D69: =D9 -> Lagos | E69: =E57 -> 8 | F69: =F57 -> Aug | G69: 2666.6667 | H69: 2566.6667 | I69: =_xlfn.XLOOKUP(D69,'Sales Manager'!$A$2:$A$6,'Sales Manager'!$B$2:$B$6,"") -> Adaora Okafor | J69: 8 | K69: 6
A70: 69 | B70: =B10+1 -> 101 | C70: =VLOOKUP(B70,Products!A:C,2,FALSE) -> Orange | D70: =D10 -> Lagos | E70: =E58 -> 9 | F70: =F58 -> Sept | G70: 1000 | H70: 700 | I70: =_xlfn.XLOOKUP(D70,'Sales Manager'!$A$2:$A$6,'Sales Manager'!$B$2:$B$6,"") -> Adaora Okafor | J70: 10 | K70: 10
A71: 70 | B71: =B11+1 -> 101 | C71: =VLOOKUP(B71,Products!A:C,2,FALSE) -> Orange | D71: =D11 -> Lagos | E71: =E59 -> 10 | F71: =F59 -> Oct | G71: 1500 | H71: 1400 | I71: =_xlfn.XLOOKUP(D71,'Sales Manager'!$A$2:$A$6,'Sales Manager'!$B$2:$B$6,"") -> Adaora Okafor | J71: 8 | K71: 5
A72: 71 | B72: =B12+1 -> 101 | C72: =VLOOKUP(B72,Products!A:C,2,FALSE) -> Orange | D72: =D12 -> Lagos | E72: =E60 -> 11 | F72: =F60 -> Nov | G72: 1333.3333 | H72: 1233.3333 | I72: =_xlfn.XLOOKUP(D72,'Sales Manager'!$A$2:$A$6,'Sales Manager'!$B$2:$B$6,"") -> Adaora Okafor | J72: 5 | K72: 5
A73: 72 | B73: =B13+1 -> 101 | C73: =VLOOKUP(B73,Products!A:C,2,FALSE) -> Orange | D73: =D13 -> Lagos | E73: =E61 -> 12 | F73: =F61 -> Dec | G73: 800 | H73: 600 | I73: =_xlfn.XLOOKUP(D73,'Sales Manager'!$A$2:$A$6,'Sales Manager'!$B$2:$B$6,"") -> Adaora Okafor | J73: 6 | K73: 7
... A601: 600 | B601: =B541+1 -> 109 | C601: =VLOOKUP(B601,Products!A:C,2,FALSE) -> Pawpaw | D601: =D541 -> Ibadan | E601: =E589 -> 12 | F601: =F589 -> Dec | G601: 2000 | H601: 1800 | I601: =_xlfn.XLOOKUP(D601,'Sales Manager'!$A$2:$A$6,'Sales Manager'!$B$2:$B$6,"") -> Funmi Adeyemi | J601: 9 | K601: 8

Sheet Products
A1: Code | B1: Prod Name
A2: 100 | B2: Mango
A3: 101 | B3: Orange
A4: 102 | B4: Banana
A5: 103 | B5: Melon
A6: 104 | B6: Apple
A7: 105 | B7: Avocado
A8: 106 | B8: Pineapple
A9: 107 | B9: Cucumber
A10: 108 | B10: Kiwi
A11: 109 | B11: Pawpaw

Sheet Sales Manager
A1: Branch | B1: Sales Manager
A2: Lagos | B2: Adaora Okafor
A3: Abuja | B3: Emeka Nwosu
A4: Ibadan | B4: Funmi Adeyemi
A5: Kaduna | B5: Musa Garba
A6: Warri | B6: Gbenga Adesanya

Sheet Pivot_Table
A2: Sales Variance by Month | G2: Monthly Profitability Trend
A3: Month | B3: Actual_Sales | C3: Sales_Budget | D3: Sum of Sales Variance Percentage | G3: SalesManager | H3: Sum of Sales Budget | I3: Sum of Actual Sales | J3: Sum of Sales Variance Percentage | K3: Sum of Net Profit Margin | L3: Sum of Net Profit Variance % | M3: Sum of △Expense Variance | P3: Products | Q3: Sum of Net Profit Margin
A4: Jan | B4: 242575 | C4: 204000 | D4: 0.18909314 | G4: Adaora Okafor | H4: 496000 | I4: 619911 | J4: 0.24982056 | K4: 0.80381592 | L4: 0.44022641 | M4: 28400 | P4: Apple - Abuja | Q4: 0.79761945
A5: Feb | B5: 267362 | C5: 222000 | D5: 0.20433333 | G5: Lagos | H5: 496000 | I5: 619911 | J5: 0.24982056 | K5: 0.80381592 | L5: 0.44022641 | M5: 28400 | P5: Apple - Ibadan | Q5: 0.80860243
A6: Mar | B6: 270309 | C6: 206000 | D6: 0.31217961 | G6: Emeka Nwosu | H6: 490000 | I6: 647694 | J6: 0.32182449 | K6: 0.78986991 | L6: 0.57316728 | M6: 28700 | P6: Apple - Kaduna | Q6: 0.74906254
A7: Apr | B7: 248987 | C7: 208000 | D7: 0.19705288 | G7: Abuja | H7: 490000 | I7: 647694 | J7: 0.32182449 | K7: 0.78986991 | L7: 0.57316728 | M7: 28700 | P7: Apple - Lagos | Q7: 0.78673544
A8: May | B8: 262487 | C8: 181000 | D8: 0.45020442 | G8: Funmi Adeyemi | H8: 506000 | I8: 594639 | J8: 0.17517589 | K8: 0.76526374 | L8: 0.34611941 | M8: 28366.667 | P8: Apple - Warri | Q8: 0.68450731
